Workbook

Sheet Summary
A1: Cost Estimate: Stress-Aware Driving App (remaining roadmap, Phases 1 to 3)
A2: Based on the AI PRD roadmap. Phase 0 (prototype) is already built and excluded. US dollars; hours and rates are assumptions you can edit.
A4: Colour legend
A5: Blue text = input
A6: Black text = formula
A7: Green text = pulled from another tab
A8: Yellow fill = key assumption to replace
A10: One-time build cost
A11: Cost item | B11: Lean | C11: Base | D11: Full | E11: Note
A12: Phase 1 Harden | B12: ='Labor Costs'!F5+'Non-Labor Costs'!H18 -> 8531.68 | C12: ='Labor Costs'!G5+'Non-Labor Costs'!I18 -> 13185.96 | D12: ='Labor Costs'!H5+'Non-Labor Costs'!J18 -> 18553.02 | E12: Labor plus non-labor.
A13: Phase 2 Validate | B13: ='Labor Costs'!F6+'Non-Labor Costs'!H19 -> 19159.9 | C13: ='Labor Costs'!G6+'Non-Labor Costs'!I19 -> 32119.85 | D13: ='Labor Costs'!H6+'Non-Labor Costs'!J19 -> 48619.75 | E13: Labor plus non-labor.
A14: Phase 3 Extend | B14: ='Labor Costs'!F7+'Non-Labor Costs'!H20 -> 17290 | C14: ='Labor Costs'!G7+'Non-Labor Costs'!I20 -> 27190 | D14: ='Labor Costs'!H7+'Non-Labor Costs'!J20 -> 38200 | E14: Labor plus non-labor.
A15: One-time subtotal | B15: =SUM(B12:B14) -> 44981.58 | C15: =SUM(C12:C14) -> 72495.81 | D15: =SUM(D12:D14) -> 105372.77
A16: Contingency | B16: =B15*Assumptions!B8 -> 6747.237 | C16: =C15*Assumptions!C8 -> 18123.952 | D16: =D15*Assumptions!D8 -> 36880.469 | E16: Subtotal × contingency %.
A17: One-time total | B17: =B15+B16 -> 51728.817 | C17: =C15+C16 -> 90619.762 | D17: =D15+D16 -> 142253.24
A19: Running cost and first-year view
A20: Cost item | B20: Lean | C20: Base | D20: Full | E20: Note
A21: Annual run cost | B21: ='Run Costs'!B12 -> 2893.9992 | C21: ='Run Costs'!C12 -> 8894.796 | D21: ='Run Costs'!D12 -> 24258.78 | E21: Steady state after build; see Run Costs tab.
A22: Build plus first year of running | B22: =B17+B21 -> 54622.816 | C22: =C17+C21 -> 99514.558 | D22: =D17+D21 -> 166512.02 | E22: One-time total + one year of run cost.
A23: Labor as share of one-time subtotal | B23: ='Labor Costs'!F8/B15 -> 0.97426547 | C23: ='Labor Costs'!G8/C15 -> 0.94797203 | D23: ='Labor Costs'!H8/D15 -> 0.9074071 | E23: Shows how much of the estimate is people time.
A24: Maintenance as share of annual run cost | B24: ='Run Costs'!B11/B21 -> 0.99516268 | C24: ='Run Costs'!C11/C21 -> 0.97135449 | D24: ='Run Costs'!D11/D21 -> 0.94975922 | E24: Shows what actually drives running cost.
A26: Reading the numbers
A27: ="Base case: about "&TEXT(C17,"$#,##0")&" to finish Phases 1 to 3, then about "&TEXT(C21,"$#,##0")&" a year to run." -> Base case: about $90,620 to finish Phases 1 to 3, then about $8,895 a year to run.
A28: ="People time is "&TEXT(C23,"0%")&" of the base build cost, so the rate and hours assumptions matter far more than hardware or SMS fees." -> People time is 95% of the base build cost, so the rate and hours assumptions matter far more than hardware or SMS fees.
A29: ="Maintenance is "&TEXT(C24,"0%")&" of base annual run cost; SMS costs are negligible at pilot volumes." -> Maintenance is 97% of base annual run cost; SMS costs are negligible at pilot volumes.
A31: Not included in this estimate
A32: 1. Real-vehicle use of any kind, ISO 26262 functional-safety validation, and regulatory approval (the PRD rules these out of the roadmap).
A33: 2. Medical-device clearance or any diagnostic claim. The product flags distress only.
A34: 3. Twilio carrier fees and US A2P registration costs for SMS; verify on Twilio's site.
A35: 4. Production cloud deployment, security audits, insurance, legal counsel beyond the allowance, taxes and shipping.
A36: 5. Phase 0 (prototype) costs, which are already incurred.
A38: Computer vision options (change in one-time total vs. plan)
A39: Option | B39: Lean | C39: Base | D39: Full | E39: Note
A40: B. Train a custom deep-learning vision model | B40: ='CV Options'!B45 -> 13752.85 | C40: ='CV Options'!C45 -> 34547.5 | D40: ='CV Options'!D45 -> 77538.6 | E40: Added cost; see CV Options tab.
A41: C. Camera only, net of AI-layer rework | B41: ='CV Options'!B47 -> -2403.3275 | C41: ='CV Options'!C47 -> 3787.75 | D41: ='CV Options'!D47 -> 16902.472 | E41: Negative = saving. Gross saving is larger; see CV Options tab.
A42: Option A (pre-trained face landmarks) is already in the plan and changes nothing.

Sheet Assumptions
A1: Assumptions
A2: Blue = input. Yellow = key assumption to replace with your own numbers. All amounts in US dollars, before tax and shipping.
A4: Scenario drivers
A5: Driver | B5: Lean (solo builder) | C5: Base (small team) | D5: Full (team + external validation) | E5: Basis
A6: Blended engineering rate ($/hour) | B6: 60 | C6: 90 | D6: 120 | E6: ASSUMPTION. Not sourced; replace with your actual rate or contractor quotes.
A7: Overhead on engineering hours (PM, QA, docs) | B7: 0.1 | C7: 0.15 | D7: 0.2 | E7: ASSUMPTION.
A8: Contingency on one-time subtotal | B8: 0.15 | C8: 0.25 | D8: 0.35 | E8: ASSUMPTION. Higher for larger scope and more unknowns.
A9: Validation study participants | B9: 5 | C9: 15 | D9: 30 | E9: ASSUMPTION. Small convenience samples; not a powered clinical study.
A10: Pilot users after build (run phase) | B10: 1 | C10: 5 | D10: 25 | E10: ASSUMPTION.
A11: Alerts per pilot user per month | B11: 1 | C11: 1 | D11: 1 | E11: ASSUMPTION. Escalations should be rare; raise to stress-test.
A12: Cloud hosting ($/month) | B12: 0 | C12: 20 | D12: 100 | E12: ASSUMPTION. The prototype runs locally; cloud is optional.
A13: Maintenance hours per month | B13: 4 | C13: 8 | D13: 16 | E13: ASSUMPTION.
A15: Unit prices
A16: Item | B16: Value | C16: Unit | E16: Basis / source
A17: Polar H10 chest sensor | B17: 89.95 | C17: USD each | E17: SOURCED (S1): US retailer listing. Other listings seen ranged from about $65 to $130.
A18: Test smartwatch | B18: 250 | C18: USD each | E18: ASSUMPTION. Not sourced; depends on the watch model chosen.
A19: Twilio SMS price per segment (US) | B19: 0.0083 | C19: USD per segment | E19: SOURCED (S2): 'starts at'. Carrier fees and registration costs are extra and not included.
A20: SMS segments per alert | B20: 2 | C20: segments | E20: ASSUMPTION. Alert text is roughly 200 characters.
A21: Cost per alert SMS | B21: =B19*B20 -> 0.0166 | C21: USD per alert | E21: Formula.
A22: Twilio local phone number rental | B22: 1.15 | C22: USD per month | E22: THIRD-PARTY (S3): summary of Twilio pricing. Verify on Twilio's site.
A23: Participant incentive | B23: 50 | C23: USD per participant | E23: ASSUMPTION.
A24: Webcam | B24: 80 | C24: USD each | E24: ASSUMPTION.

Sheet Work Breakdown
A1: Work Breakdown (base hours)
A2: Hours are engineering-judgment ASSUMPTIONS mapped to the AI PRD roadmap. Edit the blue cells; everything recalculates.
A4: Phase | B4: Work item | C4: PRD reference | D4: Base hours | E4: Note
A5: Phase 1 Harden | B5: Dead-man's alert for sensor loss | C5: FR-7 | D5: 24 | E5: Highest priority item in the PRD.
A6: Phase 1 Harden | B6: Confidence gate before intervention | C6: FR-8 | D6: 12 | E6: Minimum-readings threshold is still to be set.
A7: Phase 1 Harden | B7: Noise and outlier filter | C7: Roadmap, Phase 1 | D7: 16 | E7: Median or similar filter before scoring.
A8: Phase 1 Harden | B8: Notification retries and acknowledgment | C8: FR-17 | D8: 24
A9: Phase 1 Harden | B9: Emergency contact opt-in flow | C9: Risks table | D9: 16 | E9: Contact must agree before being alerted.
A10: Phase 1 Harden | B10: Log purge and privacy controls | C10: Risks table | D10: 12
A11: Phase 1 Harden | B11: Tests and evals for the above | C11: Evaluation plan | D11: 20
A12: Phase 2 Validate | B12: Replay eval harness | C12: Evaluation plan | D12: 40 | E12: Replays recorded sessions through the pipeline.
A13: Phase 2 Validate | B13: Session recording and labelling tools | C13: Evaluation plan | D13: 40
A14: Phase 2 Validate | B14: Skin tone and motion test protocol | C14: Evaluation plan | D14: 24
A15: Phase 2 Validate | B15: Fairness analysis against chest-strap reference | C15: Evaluation plan | D15: 32
A16: Phase 2 Validate | B16: Watch relay support (phone relay or broadcast) | C16: FR-3 | D16: 80 | E16: Largest single item; depends on the watch chosen.
A17: Phase 2 Validate | B17: Notification flow and sensor dropout evals | C17: Evaluation plan | D17: 24
A18: Phase 2 Validate | B18: Threshold tuning from recorded data | C18: AI requirements | D18: 40
A19: Phase 3 Extend | B19: Camera cross-check (face landmarks) | C19: Roadmap, Phase 3 | D19: 80
A20: Phase 3 Extend | B20: Learned model vs heuristic comparison | C20: AI requirements | D20: 100 | E20: Must beat the heuristic on recorded sessions to replace it.
A21: Phase 3 Extend | B21: Per-driver baseline profiles | C21: Roadmap, Phase 3 | D21: 40
A22: Phase 3 Extend | B22: Integration and evals | C22: Evaluation plan | D22: 40
A24: Phase 0 (Prototype) is already built and is not costed here.

Sheet Labor Costs
A1: Labor Costs by Phase
A2: Base hours × (1 + overhead) × blended rate, per scenario. Phase names must match the Work Breakdown tab.
A4: Phase | B4: Base hours | C4: Hours incl. overhead — Lean | D4: Hours incl. overhead — Base | E4: Hours incl. overhead — Full | F4: Labor cost — Lean | G4: Labor cost — Base | H4: Labor cost — Full
A5: Phase 1 Harden | B5: =SUMIF('Work Breakdown'!$A$5:$A$22,$A5,'Work Breakdown'!$D$5:$D$22) -> 124 | C5: =$B5*(1+Assumptions!B$7) -> 136.4 | D5: =$B5*(1+Assumptions!C$7) -> 142.6 | E5: =$B5*(1+Assumptions!D$7) -> 148.8 | F5: =C5*Assumptions!B$6 -> 8184 | G5: =D5*Assumptions!C$6 -> 12834 | H5: =E5*Assumptions!D$6 -> 17856
A6: Phase 2 Validate | B6: =SUMIF('Work Breakdown'!$A$5:$A$22,$A6,'Work Breakdown'!$D$5:$D$22) -> 280 | C6: =$B6*(1+Assumptions!B$7) -> 308 | D6: =$B6*(1+Assumptions!C$7) -> 322 | E6: =$B6*(1+Assumptions!D$7) -> 336 | F6: =C6*Assumptions!B$6 -> 18480 | G6: =D6*Assumptions!C$6 -> 28980 | H6: =E6*Assumptions!D$6 -> 40320
A7: Phase 3 Extend | B7: =SUMIF('Work Breakdown'!$A$5:$A$22,$A7,'Work Breakdown'!$D$5:$D$22) -> 260 | C7: =$B7*(1+Assumptions!B$7) -> 286 | D7: =$B7*(1+Assumptions!C$7) -> 299 | E7: =$B7*(1+Assumptions!D$7) -> 312 | F7: =C7*Assumptions!B$6 -> 17160 | G7: =D7*Assumptions!C$6 -> 26910 | H7: =E7*Assumptions!D$6 -> 37440
A8: Total | B8: =SUM(B5:B7) -> 664 | C8: =SUM(C5:C7) -> 730.4 | D8: =SUM(D5:D7) -> 763.6 | E8: =SUM(E5:E7) -> 796.8 | F8: =SUM(F5:F7) -> 43824 | G8: =SUM(G5:G7) -> 68724 | H8: =SUM(H5:H7) -> 95616

Sheet Non-Labor Costs
A1: Non-Labor Costs
A2: Quantity × unit price per scenario. Allowance rows use a unit price of $1, so the quantity is the dollar amount.
A4: Phase | B4: Item | C4: Unit | D4: Unit price | E4: Qty — Lean | F4: Qty — Base | G4: Qty — Full | H4: Cost — Lean | I4: Cost — Base | J4: Cost — Full | K4: Note
A5: Phase 1 Harden | B5: Polar H10 sensors for development | C5: each | D5: =Assumptions!B17 -> 89.95 | E5: 1 | F5: 1 | G5: 2 | H5: =$D5*E5 -> 89.95 | I5: =$D5*F5 -> 89.95 | J5: =$D5*G5 -> 179.9 | K5: Chest strap used as the BLE reference sensor.
A6: Phase 1 Harden | B6: Test smartwatch for relay and wear checks | C6: each | D6: =Assumptions!B18 -> 250 | E6: 1 | F6: 1 | G6: 2 | H6: =$D6*E6 -> 250 | I6: =$D6*F6 -> 250 | J6: =$D6*G6 -> 500
A7: Phase 1 Harden | B7: Twilio number rental during build | C7: month | D7: =Assumptions!B22 -> 1.15 | E7: 6 | F7: 9 | G7: 12 | H7: =$D7*E7 -> 6.9 | I7: =$D7*F7 -> 10.35 | J7: =$D7*G7 -> 13.8 | K7: Spans all three phases.
A8: Phase 1 Harden | B8: Test alert SMS messages | C8: message | D8: =Assumptions!B21 -> 0.0166 | E8: 50 | F8: 100 | G8: 200 | H8: =$D8*E8 -> 0.83 | I8: =$D8*F8 -> 1.66 | J8: =$D8*G8 -> 3.32 | K8: Carrier fees not included.
A9: Phase 2 Validate | B9: Reference chest-strap sensors for validation study | C9: each | D9: =Assumptions!B17 -> 89.95 | E9: 2 | F9: 3 | G9: 5 | H9: =$D9*E9 -> 179.9 | I9: =$D9*F9 -> 269.85 | J9: =$D9*G9 -> 449.75 | K9: Used as ground truth against wrist data.
A10: Phase 2 Validate | B10: Additional test watch models | C10: each | D10: =Assumptions!B18 -> 250 | E10: 1 | F10: 2 | G10: 3 | H10: =$D10*E10 -> 250 | I10: =$D10*F10 -> 500 | J10: =$D10*G10 -> 750
A11: Phase 2 Validate | B11: Participant incentives | C11: participant | D11: =Assumptions!B23 -> 50 | E11: =Assumptions!B9 -> 5 | F11: =Assumptions!C9 -> 15 | G11: =Assumptions!D9 -> 30 | H11: =$D11*E11 -> 250 | I11: =$D11*F11 -> 750 | J11: =$D11*G11 -> 1500 | K11: Linked to the participants driver.
A12: Phase 2 Validate | B12: Ethics and legal review allowance | C12: USD | D12: 1 | E12: 0 | F12: 1500 | G12: 5000 | H12: =$D12*E12 -> 0 | I12: =$D12*F12 -> 1500 | J12: =$D12*G12 -> 5000 | K12: ASSUMPTION. Human-subject data collection may need formal review; confirm with your institution.
A13: Phase 2 Validate | B13: Data storage and tooling for recorded sessions | C13: USD | D13: 1 | E13: 0 | F13: 120 | G13: 600 | H13: =$D13*E13 -> 0 | I13: =$D13*F13 -> 120 | J13: =$D13*G13 -> 600 | K13: ASSUMPTION.
A14: Phase 3 Extend | B14: Webcam for camera cross-check | C14: each | D14: =Assumptions!B24 -> 80 | E14: 1 | F14: 1 | G14: 2 | H14: =$D14*E14 -> 80 | I14: =$D14*F14 -> 80 | J14: =$D14*G14 -> 160
A15: Phase 3 Extend | B15: Cloud compute for model comparison | C15: USD | D15: 1 | E15: 50 | F15: 200 | G15: 600 | H15: =$D15*E15 -> 50 | I15: =$D15*F15 -> 200 | J15: =$D15*G15 -> 600 | K15: ASSUMPTION. The model is expected to be small.
A17: Totals by phase
A18: Phase 1 Harden | H18: =SUMIF($A$5:$A$15,$A18,H$5:H$15) -> 347.68 | I18: =SUMIF($A$5:$A$15,$A18,I$5:I$15) -> 351.96 | J18: =SUMIF($A$5:$A$15,$A18,J$5:J$15) -> 697.02
A19: Phase 2 Validate | H19: =SUMIF($A$5:$A$15,$A19,H$5:H$15) -> 679.9 | I19: =SUMIF($A$5:$A$15,$A19,I$5:I$15) -> 3139.85 | J19: =SUMIF($A$5:$A$15,$A19,J$5:J$15) -> 8299.75
A20: Phase 3 Extend | H20: =SUMIF($A$5:$A$15,$A20,H$5:H$15) -> 130 | I20: =SUMIF($A$5:$A$15,$A20,I$5:I$15) -> 280 | J20: =SUMIF($A$5:$A$15,$A20,J$5:J$15) -> 760
A21: Total | H21: =SUM(H18:H20) -> 1157.58 | I21: =SUM(I18:I20) -> 3771.81 | J21: =SUM(J18:J20) -> 9756.77

Sheet Run Costs
A1: Annual Run Costs (steady state after build)
A2: Recurring costs once the product is running with pilot users.
A4: Item | B4: Lean | C4: Base | D4: Full | E4: Note
A5: Pilot users | B5: =Assumptions!B10 -> 1 | C5: =Assumptions!C10 -> 5 | D5: =Assumptions!D10 -> 25 | E5: Linked.
A6: Alerts per user per month | B6: =Assumptions!B11 -> 1 | C6: =Assumptions!C11 -> 1 | D6: =Assumptions!D11 -> 1 | E6: Linked.
A7: Alerts per year | B7: =B5*B6*12 -> 12 | C7: =C5*C6*12 -> 60 | D7: =D5*D6*12 -> 300 | E7: Users × alerts × 12 months.
A8: SMS cost per year | B8: =B7*Assumptions!$B$21 -> 0.1992 | C8: =C7*Assumptions!$B$21 -> 0.996 | D8: =D7*Assumptions!$B$21 -> 4.98 | E8: Alerts × cost per alert SMS. Carrier fees not included.
A9: Twilio number rental per year | B9: =12*Assumptions!$B$22 -> 13.8 | C9: =12*Assumptions!$B$22 -> 13.8 | D9: =12*Assumptions!$B$22 -> 13.8 | E9: Local number, 12 months.
A10: Cloud hosting per year | B10: =Assumptions!B12*12 -> 0 | C10: =Assumptions!C12*12 -> 240 | D10: =Assumptions!D12*12 -> 1200 | E10: Zero if you keep running locally.
A11: Maintenance labor per year | B11: =Assumptions!B13*12*Assumptions!B6 -> 2880 | C11: =Assumptions!C13*12*Assumptions!C6 -> 8640 | D11: =Assumptions!D13*12*Assumptions!D6 -> 23040 | E11: Hours per month × 12 × blended rate.
A12: Annual run cost | B12: =SUM(B8:B11) -> 2893.9992 | C12: =SUM(C8:C11) -> 8894.796 | D12: =SUM(D8:D11) -> 24258.78 | E12: Sum of SMS, number rental, hosting and maintenance.

Sheet CV Options
A1: Computer Vision Options (change vs. the plan)
A2: Illustrative comparison. Option A (pre-trained face landmarks) is already in the plan; B and C show what changes. Blue = input.
A4: Inputs (assumptions)
A5: Input | B5: Lean | C5: Base | D5: Full | E5: Basis
A6: Extra engineering hours for a custom CV model | B6: 160 | C6: 240 | D6: 360 | E6: ASSUMPTION. Data collection and labelling tools, training, evaluation, edge optimisation.
A7: Extra participants for face-video data | B7: 25 | C7: 50 | D7: 100 | E7: ASSUMPTION.
A8: Extra GPU hours for training | B8: 100 | C8: 200 | D8: 400 | E8: ASSUMPTION.
A9: GPU price ($/hour, A100 80GB) | B9: 1.49 | C9: 1.49 | D9: 1.49 | E9: SOURCED (S5): low-cost provider list price. Big cloud providers charge about $3.67 to $5.03 (S6).
A10: Rework hours if the heart signal is dropped (camera only) | B10: 60 | C10: 120 | D10: 180 | E10: ASSUMPTION. The AI layer's scoring is built on BPM and HRV.
A11: Sensor and watch hardware still needed (camera only) | B11: 0 | C11: 0 | D11: 0 | E11: ASSUMPTION. Raise above 0% if you keep a reference sensor.
A13: Baseline pulled from the main model
A14: Item | B14: Lean | C14: Base | D14: Full | E14: Note
A15: Camera cross-check base hours (Phase 3) | B15: =INDEX('Work Breakdown'!$D$5:$D$22,MATCH("Camera cross-check (face landmarks)",'Work Breakdown'!$B$5:$B$22,0)) -> 80 | C15: =INDEX('Work Breakdown'!$D$5:$D$22,MATCH("Camera cross-check (face landmarks)",'Work Breakdown'!$B$5:$B$22,0)) -> 80 | D15: =INDEX('Work Breakdown'!$D$5:$D$22,MATCH("Camera cross-check (face landmarks)",'Work Breakdown'!$B$5:$B$22,0)) -> 80 | E15: Looked up from the Work Breakdown tab.
A16: Camera cross-check labor (incl. overhead) | B16: =B15*(1+Assumptions!B7)*Assumptions!B6 -> 5280 | C16: =C15*(1+Assumptions!C7)*Assumptions!C6 -> 8280 | D16: =D15*(1+Assumptions!D7)*Assumptions!D6 -> 11520 | E16: Hours × (1 + overhead) × blended rate.
A17: Webcam | B17: ='Non-Labor Costs'!H14 -> 80 | C17: ='Non-Labor Costs'!I14 -> 80 | D17: ='Non-Labor Costs'!J14 -> 160 | E17: From the Non-Labor Costs tab.
A18: Camera cross-check cost incl. contingency (already in plan) | B18: =(B16+B17)*(1+Assumptions!B8) -> 6164 | C18: =(C16+C17)*(1+Assumptions!C8) -> 10450 | D18: =(D16+D17)*(1+Assumptions!D8) -> 15768 | E18: Option A. Included in the Summary totals.
A19: Baseline one-time total (main model) | B19: =Summary!B17 -> 51728.817 | C19: =Summary!C17 -> 90619.762 | D19: =Summary!D17 -> 142253.24 | E19: Summary tab, one-time total.
A21: Option B: train a custom deep-learning vision model (added cost)
A22: Item | B22: Lean | C22: Base | D22: Full | E22: Note
A23: Extra engineering labor | B23: =B6*(1+Assumptions!B7)*Assumptions!B6 -> 10560 | C23: =C6*(1+Assumptions!C7)*Assumptions!C6 -> 24840 | D23: =D6*(1+Assumptions!D7)*Assumptions!D6 -> 51840 | E23: Extra hours × (1 + overhead) × rate.
A24: Extra participant incentives | B24: =B7*Assumptions!$B$23 -> 1250 | C24: =C7*Assumptions!$B$23 -> 2500 | D24: =D7*Assumptions!$B$23 -> 5000 | E24: Extra participants × incentive per participant.
A25: Extra GPU compute | B25: =B8*B9 -> 149 | C25: =C8*C9 -> 298 | D25: =D8*D9 -> 596 | E25: GPU hours × GPU price. Small next to labor.
A26: Added subtotal | B26: =SUM(B23:B25) -> 11959 | C26: =SUM(C23:C25) -> 27638 | D26: =SUM(D23:D25) -> 57436
A27: Added contingency | B27: =B26*Assumptions!B8 -> 1793.85 | C27: =C26*Assumptions!C8 -> 6909.5 | D27: =D26*Assumptions!D8 -> 20102.6 | E27: Same contingency % as the main model.
A28: Added one-time cost | B28: =B26+B27 -> 13752.85 | C28: =C26+C27 -> 34547.5 | D28: =D26+D27 -> 77538.6
A29: Change vs. plan | B29: =B28/B19 -> 0.26586438 | C29: =C28/C19 -> 0.38123583 | D29: =D28/D19 -> 0.54507441 | E29: Added cost ÷ baseline one-time total.
A31: Option C: camera only (drop the watch and sensor work)
A32: Item | B32: Lean | C32: Base | D32: Full | E32: Note
A33: Watch relay work avoided (FR-3 base hours) | B33: =INDEX('Work Breakdown'!$D$5:$D$22,MATCH("FR-3",'Work Breakdown'!$C$5:$C$22,0)) -> 80 | C33: =INDEX('Work Breakdown'!$D$5:$D$22,MATCH("FR-3",'Work Breakdown'!$C$5:$C$22,0)) -> 80 | D33: =INDEX('Work Breakdown'!$D$5:$D$22,MATCH("FR-3",'Work Breakdown'!$C$5:$C$22,0)) -> 80 | E33: Looked up from the Work Breakdown tab.
A34: Watch relay labor avoided | B34: =B33*(1+Assumptions!B7)*Assumptions!B6 -> 5280 | C34: =C33*(1+Assumptions!C7)*Assumptions!C6 -> 8280 | D34: =D33*(1+Assumptions!D7)*Assumptions!D6 -> 11520 | E34: Hours × (1 + overhead) × rate.
A35: Sensor and watch hardware avoided | B35: =('Non-Labor Costs'!H5+'Non-Labor Costs'!H6+'Non-Labor Costs'!H9+'Non-Labor Costs'!H10)*(1-B11) -> 769.85 | C35: =('Non-Labor Costs'!I5+'Non-Labor Costs'!I6+'Non-Labor Costs'!I9+'Non-Labor Costs'!I10)*(1-C11) -> 1109.8 | D35: =('Non-Labor Costs'!J5+'Non-Labor Costs'!J6+'Non-Labor Costs'!J9+'Non-Labor Costs'!J10)*(1-D11) -> 1879.65 | E35: Phase 1 and 2 sensors and watches, less any hardware still needed.
A36: Subtotal avoided | B36: =B34+B35 -> 6049.85 | C36: =C34+C35 -> 9389.8 | D36: =D34+D35 -> 13399.65
A37: Contingency avoided | B37: =B36*Assumptions!B8 -> 907.4775 | C37: =C36*Assumptions!C8 -> 2347.45 | D37: =D36*Assumptions!D8 -> 4689.8775
A38: Gross saving | B38: =B36+B37 -> 6957.3275 | C38: =C36+C37 -> 11737.25 | D38: =D36+D37 -> 18089.528 | E38: Before any rework.
A39: Rework of AI layer without the heart signal (incl. contingency) | B39: =B10*(1+Assumptions!B7)*Assumptions!B6*(1+Assumptions!B8) -> 4554 | C39: =C10*(1+Assumptions!C7)*Assumptions!C6*(1+Assumptions!C8) -> 15525 | D39: =D10*(1+Assumptions!D7)*Assumptions!D6*(1+Assumptions!D8) -> 34992 | E39: Rework hours × (1 + overhead) × rate × (1 + contingency).
A40: Net change (negative = saving) | B40: =B39-B38 -> -2403.3275 | C40: =C39-C38 -> 3787.75 | D40: =D39-D38 -> 16902.472 | E40: Rework minus gross saving.
A41: Net change vs. plan | B41: =B40/B19 -> -0.046460129 | C41: =C40/C19 -> 0.041798278 | D41: =D40/D19 -> 0.1188196 | E41: Net change ÷ baseline one-time total.
A43: Comparison: change in one-time total vs. plan
A44: Option | B44: Lean | C44: Base | D44: Full | E44: Note
A45: B. Custom deep-learning vision model | B45: =B28 -> 13752.85 | C45: =C28 -> 34547.5 | D45: =D28 -> 77538.6 | E45: Added cost.
...

Sheet Sources
A1: Sources and Limitations
A2: Prices retrieved October 2026. Everything not listed here is an assumption, marked as such on the Assumptions tab.
A4: ID | B4: Source | C4: Used for | D4: Type | E4: URL | F4: Note
A5: S1 | B5: PlayBetter: Polar H10 Heart Rate Monitor listing | C5: Chest sensor price ($89.95) | D5: US retailer listing | E5: https://www.playbetter.com/collections/polar-heart-rate-monitors | F5: Retail prices vary by seller and sale; listings seen ranged from about $65 to $130.
A6: S2 | B6: Twilio: SMS pricing (United States) | C6: SMS price per segment ($0.0083, 'starts at') | D6: Vendor pricing page | E6: https://www.twilio.com/en-us/sms/pricing | F6: Page states pricing current as of August 2026. Carrier fees are additional.
A7: S3 | B7: Textus: Twilio pricing overview | C7: Local number rental ($1.15/month) | D7: Third-party summary | E7: https://textus.com/blog/twilio-pricing | F7: Not from Twilio directly; verify before committing.
A8: S4 | B8: Stress-Aware Driving App: AI PRD (this conversation) | C8: Roadmap phases, requirement IDs, scope limits | D8: Internal document | F8: Defines the work items costed in the Work Breakdown tab.
A9: S5 | B9: Jarvislabs: NVIDIA A100 GPU price in 2026 | C9: GPU price ($1.49/hour, A100 80GB on demand) | D9: Provider blog | E9: https://docs.jarvislabs.ai/blog/a100-price | F9: Snapshot from March 2026; GPU prices change often.
A10: S6 | B10: Hostinger: Cloud GPU pricing compared (2026) | C10: Context: big cloud providers charge about $3.67 to $5.03 per A100 hour | D10: Third-party comparison | E10: https://www.hostinger.com/tutorials/?p=158956 | F10: Prices as of September 2026.
A12: Limitations
A13: 1. Engineering hours, rates, allowances and participant counts are assumptions, not quotes. Replace the yellow and blue cells with your own numbers.
A14: 2. No salary or contractor-rate source was used; the rate drivers are placeholders for your actual cost.
A15: 3. Hardware prices change by retailer and season. The estimate uses one retailer's list price.
A16: 4. The computer vision options use illustrative hours, participant counts and GPU hours that are assumptions, not measurements.
A17: 5. The estimate covers the PRD's Phases 1 to 3 only, in US dollars, and is an order-of-magnitude planning aid rather than a bid.
