Workbook

Sheet Summary
A1: Stress, Heart Disease & Driving — Research Worksheet
A2: US-focused. Compiled October 2026 from public sources listed on the 'Sources' tab. Prototype research aid for the stress-aware driving project.
A4: Colour legend
A5: Blue text = sourced data or hard-coded input
A6: Black text = formula / calculation
A7: Green text = value pulled from another tab
A8: Yellow fill = assumption you can change
A10: Headline numbers (all linked to other tabs)
A11: Metric | B11: Value | C11: Where to look
A12: US heart disease deaths (2024) | B12: ='Leading Causes'!C5 -> 683491 | C12: Leading Causes
A13: Heart disease as share of all US deaths | B13: ='Leading Causes'!D5 -> 0.22244234 | C13: Leading Causes
A14: Heart disease + stroke as share of all US deaths | B14: ='Leading Causes'!D18 -> 0.27674436 | C14: Leading Causes
A15: US heart attacks per year | B15: ='Attribution Calc'!B5 -> 805000 | C15: Attribution Calc
A16: Heart attacks per year attributable to job strain (base case, if causal) | B16: ='Attribution Calc'!B12 -> 27370 | C16: Attribution Calc (yellow cell B9 = assumption)
A17: …deaths among those heart attacks per year | B17: ='Attribution Calc'!B13 -> 3284.4 | C17: Attribution Calc
A18: US traffic deaths (2024) | B18: ='Crash Estimates'!C5 -> 39254 | C18: Crash Estimates
A19: Share of drivers in crashes precipitated by any medical emergency | B19: ='Crash Estimates'!C7 -> 0.013 | C19: Crash Estimates
A20: Est. heart-linked crash deaths per year — low scenario (illustrative) | B20: ='Crash Estimates'!D27 -> 81.64832 | C20: Crash Estimates
A21: Est. heart-linked crash deaths per year — high scenario (illustrative) | B21: ='Crash Estimates'!D28 -> 824.334 | C21: Crash Estimates
A22: Est. heart-linked crash deaths per year — midpoint (illustrative) | B22: ='Crash Estimates'!D29 -> 445.2831 | C22: Crash Estimates
A24: Key takeaways
A25: 1. Heart disease is the leading cause of death in the US. Adding stroke, cardiovascular causes make up a large share of all deaths (see rows above).
A26: 2. In observational studies, stress is linked to higher heart attack risk (roughly 1.2× to 6× depending on exposure and design), but the share of heart attacks attributable to job strain is modest (~3.4%) compared with smoking (~36%).
A27: 3. Driver heart events cause a small share of crashes, but those crashes are more often single-vehicle and severe. In autopsy series, most drivers who suffered cardiac arrest at the wheel managed to stop the vehicle.
A28: 4. Most cardiac deaths at the wheel occur in drivers with a known cardiac history — an identifiable higher-risk group (Birmingham series).
A29: 5. Heart-linked crash deaths cannot be counted directly; 'Crash Estimates' shows an illustrative range from several methods. Treat it as order of magnitude only.
A30: 6. Heart rate and HRV alone cannot distinguish stress from an ischemic event, so a stress-detection system should not claim to detect heart attacks.
A32: Tab guide
A33: Leading Causes | B33: Top 10 US causes of death (2024) with heart disease highlighted, plus chart.
A34: Stress Evidence | B34: Studies linking stress to heart attack risk, with relative risks and caveats.
A35: Attribution Calc | B35: Adjustable calculator: how many heart attacks/deaths might stress account for.
A36: Crash Estimates | B36: Adjustable scenarios for US crash deaths linked to a driver's heart condition.
A37: Crash Case Data | B37: Study-level breakdown of people who die in crashes linked to heart conditions.
A38: Sources | B38: Full source list with URLs, source type, quality notes and limitations.

Sheet Leading Causes
A1: Leading Causes of Death — United States, 2024
A2: Underlying cause of death. Source S1 (CDC/NCHS, Mortality in the United States, 2024). Blue = sourced data; black = formula.
A4: Rank | B4: Cause of death | C4: Deaths (2024) | D4: % of all deaths | E4: Cardio-vascular? | F4: Stress / heart link covered in this workbook
A5: =RANK(C5,$C$5:$C$14) -> 1 | B5: Heart disease | C5: 683491 | D5: =C5/$C$16 -> 0.22244234 | E5: Yes | F5: Yes — see 'Stress Evidence' and 'Attribution Calc'. Stress is associated with higher heart attack risk (observational evidence).
A6: =RANK(C6,$C$5:$C$14) -> 2 | B6: Cancer | C6: 619876 | D6: =C6/$C$16 -> 0.20173882 | E6: No | F6: Not assessed.
A7: =RANK(C7,$C$5:$C$14) -> 3 | B7: Accidents (unintentional injuries) | C7: 197449 | D7: =C7/$C$16 -> 0.064259832 | E7: No | F7: Indirect — traffic crashes caused by a driver's heart condition; see 'Crash Estimates' and 'Crash Case Data'.
A8: =RANK(C8,$C$5:$C$14) -> 4 | B8: Stroke (cerebrovascular diseases) | C8: 166852 | D8: =C8/$C$16 -> 0.05430203 | E8: Yes | F8: Partial — a post-9/11 study counted strokes among stress-linked cardiovascular ailments (S9). Not otherwise assessed.
A9: =RANK(C9,$C$5:$C$14) -> 5 | B9: Chronic lower respiratory diseases | C9: 145643 | D9: =C9/$C$16 -> 0.047399555 | E9: No | F9: Not assessed.
A10: =RANK(C10,$C$5:$C$14) -> 6 | B10: Alzheimer's disease | C10: 116022 | D10: =C10/$C$16 -> 0.037759392 | E10: No | F10: Not assessed.
A11: =RANK(C11,$C$5:$C$14) -> 7 | B11: Diabetes | C11: 94445 | D11: =C11/$C$16 -> 0.030737151 | E11: No | F11: Not assessed (diabetic reactions do appear among driver medical emergencies; see 'Crash Case Data').
A12: =RANK(C12,$C$5:$C$14) -> 8 | B12: Nephritis, nephrotic syndrome, nephrosis | C12: 55081 | D12: =C12/$C$16 -> 0.017926127 | E12: No | F12: Not assessed.
A13: =RANK(C13,$C$5:$C$14) -> 9 | B13: Chronic liver disease and cirrhosis | C13: 52274 | D13: =C13/$C$16 -> 0.017012588 | E13: No | F13: Not assessed.
A14: =RANK(C14,$C$5:$C$14) -> 10 | B14: Suicide | C14: 48824 | D14: =C14/$C$16 -> 0.015889784 | E14: No | F14: Not assessed.
B16: All causes (total deaths, 2024) | C16: 3072666 | D16: =C16/$C$16 -> 1
B17: Top-10 causes combined | C17: =SUM(C5:C14) -> 2179957 | D17: =C17/$C$16 -> 0.70946761
B18: Heart disease + stroke (cardiovascular) | C18: =C5+C8 -> 850343 | D18: =C18/$C$16 -> 0.27674436
A20: Context: heart disease deaths vs. heart attacks vs. traffic deaths
B21: Measure | C21: Value | F21: Note
B22: US heart attacks per year (CDC) | C22: ='Attribution Calc'!B5 -> 805000 | F22: Heart attacks are one event type within heart disease; not every heart attack is fatal.
B23: Heart disease deaths (2024) | C23: =C5 -> 683491
B24: US traffic deaths, 2024 (NHTSA) | C24: ='Crash Estimates'!C5 -> 39254
B25: Heart disease deaths per traffic death | C25: =C23/C24 -> 17.412009
B26: Traffic deaths as % of unintentional-injury deaths (approx.) | C26: =C24/C7 -> 0.19880577 | F26: Approximate: NHTSA and CDC define and count deaths differently (different agencies, case definitions).

Sheet Stress Evidence
A1: Evidence Linking Stress to Heart Attack Risk
A2: Relative risk (RR) = how many times more likely vs. an unexposed group. Almost all of this evidence is observational — association, not proven causation.
A4: # | B4: Study / event | C4: Population / design | D4: Exposure | E4: Metric | F4: Value | G4: Unit | H4: Plain-language finding | I4: Source ID | J4: Source type | K4: Limitations
A5: 1 | B5: Job-strain meta-analysis (Kivimäki et al., Lancet) | C5: ~200,000 Europeans, no prior heart disease; 13 studies; ~7.5-yr follow-up | D5: High job strain (heavy demands, little control) | E5: Relative risk | F5: 1.23 | G5: × risk (RR) | H5: People in high-strain jobs were 23% more likely to have a heart attack. | I5: S4, S5 | J5: News report of peer-reviewed study | K5: Authors state this shows association, not causation (S5).
A6: 2 | B6: Job-strain meta-analysis — attributable share | C6: Same as above | D6: High job strain | E6: Attributable fraction | F6: 0.034 | G6: % of heart attacks | H6: If the link were causal, ~3.4% of heart attacks would be attributable to job strain (vs. ~36% for smoking). | I6: S4, S5 | J6: News report of peer-reviewed study | K6: Europe-only workforce sample; 'if causal' estimate.
A7: 3 | B7: INTERHEART (Rosengren et al., Lancet 2004) | C7: >24,000 people, 52 countries; half had a heart attack (case-control) | D7: Persistent severe stress | E7: Relative risk | F7: 2.5 | G7: × risk (RR) | H7: Persistent severe stress was linked to ~2.5× higher heart attack risk. | I7: S6 | J7: Summary of peer-reviewed study | K7: Case-control: stress measured by recall after the event; recall bias possible.
A8: 4 | B8: INTERHEART — stress plus depression | C8: Same as above | D8: Stress and depression together | E8: Relative risk | F8: 3 | G8: × risk (RR) | H8: Stress combined with depression was linked to roughly threefold risk. | I8: S6 | J8: Summary of peer-reviewed study | K8: Same limitations as above.
A9: 5 | B9: INTERHEART — smoking (comparator) | C9: Same as above | D9: Smoking | E9: Relative risk | F9: 3 | G9: × risk (RR) ≈ | H9: Smoking raised risk 'nearly three times' — shown as ≈3.0 for comparison with stress. | I9: S6 | J9: Summary of peer-reviewed study | K9: Source gives 'nearly 3×'; 3.0 is an approximation.
A10: 6 | B10: SHEEP — sudden job stress (Stockholm) | C10: 1,381 people who had a first heart attack; case-crossover design | D10: Sudden intense job stress in prior 24 hours | E10: Relative risk (24 h) | F10: 6 | G10: × risk (RR) | H10: Sudden job stress was linked to ~6× higher risk of a heart attack within 24 hours. | I10: S7 | J10: News report of peer-reviewed study | K10: Small sample of prior-MI patients; self-reported stress.
A11: 7 | B11: Post-9/11 stress (Holman et al., UC Irvine) | C11: National sample surveyed after 9/11, followed up to 3 years | D11: High acute stress response after 9/11 | E11: Increase in incidence | F11: 0.53 | G11: % increase | H11: Acute stress responses linked to a 53% higher incidence of cardiovascular ailments (incl. stroke, high blood pressure). | I11: S9 | J11: News report of peer-reviewed study | K11: Self-reported diagnoses; 'ailments' are broader than heart attacks.
A12: 8 | B12: Holiday-period heart deaths (AHA study) | C12: US heart-related deaths, Dec 25 – Jan 7 | D12: Holiday period (stress hypothesized) | E12: Increase in deaths | F12: 0.042 | G12: % increase | H12: 4.2% more heart-related deaths in the holiday window. | I12: S10 | J12: News report of study | K12: Stress is only one possible explanation (cold, diet, delayed care).
A14: Calculated indicator: Hurricane Katrina (Tulane University Hospital) — source S8
B15: Period | C15: Heart attack admissions | D15: Total admissions | E15: Heart attacks as % of admissions
B16: Two years before Katrina | C16: 150 | D16: 21229 | E16: =C16/D16 -> 0.0070658062
B17: Two years after hospital reopened | C17: 246 | D17: 11282 | E17: =C17/D17 -> 0.021804645
B18: Ratio (after ÷ before) | E18: =E17/E16 -> 3.0859387
B19: Caveat: patient mix and hospital catchment changed after the storm; researchers noted higher smoking/substance use and missed medications.
A21: Chart data: relative risk comparison (linked to table above)
B22: Exposure | C22: Relative risk
B23: Job strain | C23: =F5 -> 1.23
B24: INTERHEART: severe stress | C24: =F7 -> 2.5
B25: INTERHEART: stress + depression | C25: =F8 -> 3
B26: INTERHEART: smoking (≈) | C26: =F9 -> 3
B27: SHEEP: sudden job stress (24 h) | C27: =F10 -> 6

Sheet Attribution Calc
A1: How Many Heart Attacks Might Stress Account For?
A2: Illustrative arithmetic using published inputs. Yellow cells are assumptions you can change. This is NOT a published statistic.
A4: Input | B4: Value | C4: Unit | D4: Source / note
A5: US heart attacks per year | B5: 805000 | C5: heart attacks / yr | D5: S2 (CDC Heart Disease Facts). Includes first-time and recurrent heart attacks.
A6: …of which first heart attack | B6: 605000 | C6: heart attacks / yr | D6: S2
A7: …of which recurrent | B7: =B5-B6 -> 200000 | C7: heart attacks / yr | D7: Formula; matches CDC's ~200,000 recurrent.
A8: Case fatality — share of heart attack patients who die | B8: 0.12 | C8: % of heart attacks | D8: S3 (secondary summary of CDC data: 'about 12 percent'). Verify against CDC before citing.
A9: Attributable fraction — job strain (base case) | B9: 0.034 | C9: % of heart attacks | D9: S4/S5: ~3.4% of heart attacks attributable to job strain, if the link is causal (European workers). ASSUMPTION — change to test.
A11: Estimated impact (base case)
A12: Heart attacks attributable to job strain, per year | B12: =B5*B9 -> 27370 | C12: heart attacks / yr | D12: Formula: US heart attacks × attributable fraction
A13: Deaths among those heart attacks, per year | B13: =B12*B8 -> 3284.4 | C13: deaths / yr | D13: Formula: attributable heart attacks × case fatality
A14: Attributable heart attacks per day | B14: =B12/365 -> 74.986301 | C14: heart attacks / day
A15: Caveat: covers job strain only (not all stress), extrapolates European findings to the US, and assumes causation the study did not prove.
A17: Sensitivity: what if the attributable fraction were different? (illustrative — not published estimates)
A18: Attributable fraction | B18: Heart attacks / yr | C18: Deaths / yr | D18: Note
A19: 0.01 | B19: =$B$5*A19 -> 8050 | C19: =B19*$B$8 -> 966 | D19: Low illustration
A20: =B9 -> 0.034 | B20: =$B$5*A20 -> 27370 | C20: =B20*$B$8 -> 3284.4 | D20: Base case (linked to B9)
A21: 0.05 | B21: =$B$5*A21 -> 40250 | C21: =B21*$B$8 -> 4830 | D21: Illustration
A22: 0.1 | B22: =$B$5*A22 -> 80500 | C22: =B22*$B$8 -> 9660 | D22: Illustration
A23: 0.15 | B23: =$B$5*A23 -> 120750 | C23: =B23*$B$8 -> 14490 | D23: Illustration
A24: 0.2 | B24: =$B$5*A24 -> 161000 | C24: =B24*$B$8 -> 19320 | D24: Illustration
A26: Context: other attributable shares reported alongside job strain (shares overlap; they do not sum to 100%)
A27: Risk factor | B27: Attributable share | C27: Implied heart attacks / yr | D27: Source / note
A28: Smoking | B28: 0.36 | C28: =$B$5*B28 -> 289800 | D28: S4 (ISHN report of Lancet study)
A29: Physical inactivity — as reported by ISHN | B29: 0.12 | C29: =$B$5*B29 -> 96600 | D29: S4. Conflicts with TIME's figure below; sources differ.
A30: Physical inactivity — as reported by TIME | B30: 0.2 | C30: =$B$5*B30 -> 161000 | D30: S5. Conflicts with ISHN's figure above; sources differ.
A31: Job strain (base case) | B31: =B9 -> 0.034 | C31: =$B$5*B31 -> 27370 | D31: Linked to B9

Sheet Crash Estimates
A1: US Crash Deaths Linked to a Driver's Heart Condition — Scenario Estimates
A2: No official count exists. Everything below is illustrative scenario arithmetic, NOT published statistics. Yellow cells are assumptions you can change.
A4: ID | B4: Input | C4: Value | D4: Source ID | F4: Source / note
A5: I1 | B5: US traffic deaths — 2024 (confirmed) | C5: 39254 | D5: S11 | F5: NHTSA, as reported by Trucknews.
A6: I2 | B6: US traffic deaths — 2025 (NHTSA projection) | C6: 36640 | D6: S11, S12 | F6: Projection, not final; NHTSA is still finalizing 2025 data.
A7: I3 | B7: Share of drivers in crashes precipitated by a medical emergency (any) | C7: 0.013 | D7: S13 | F7: NHTSA NMVCCS survey (light passenger vehicles). Share of drivers/crashes, not of deaths.
A8: I4 | B8: …share of those that were seizures, blackouts or diabetic reactions | C8: 0.84 | D8: S13 | F8: NMVCCS.
A9: I5 | B9: …remainder (cardiac events + all other causes) — UPPER BOUND for cardiac | C9: =1-C8 -> 0.16 | D9: — | F9: Inference: cardiac events sit inside this remainder, but so do other causes. No cardiac-only share found.
A10: I6 | B10: Incapacitating injury or death — medical-emergency crashes | C10: 0.28 | D10: S23 | F10: NHTSA 2009 study as summarized by Lievers.
A11: I7 | B11: Incapacitating injury or death — other crashes | C11: 0.11 | D11: S23 | F11: Same source.
A12: I8 | B12: Severity ratio (medical-emergency vs other crashes) | C12: =C10/C11 -> 2.5454545 | D12: — | F12: Formula. Combines injury and death, so only a rough severity proxy.
A13: I9 | B13: Probable cardiac arrest — % of driver deaths, Vaud (Switzerland) | C13: 0.017 | D13: S15 | F13: 1986-89 data. Share of DRIVER deaths.
A14: I10 | B14: Probable cardiac arrest — % of driver deaths, Finland | C14: 0.021 | D14: S15 | F14: 1984-89 data. Share of DRIVER deaths.
A15: I11 | B15: Sudden driver incapacity (all causes) — % of traffic deaths, Finland | C15: 0.015 | D15: S15 | F15: Not heart-specific.
A16: I12 | B16: Sudden driver incapacity (all causes) — % of traffic deaths, Vaud | C16: 0.034 | D16: S15 | F16: Not heart-specific.
A17: I13 | B17: Range of crashes from any acute medical illness — low end | C17: 0.001 | D17: S14 | F17: Review: estimates range from <0.1% to 3% across studies.
A18: I14 | B18: Range of crashes from any acute medical illness — high end | C18: 0.03 | D18: S14 | F18: Same review.
A20: Scenarios: estimated US crash deaths linked to a driver's heart condition
A21: ID | B21: Scenario & method | C21: Share of traffic deaths applied | D21: Est. deaths — 2024 base | E21: Est. deaths — 2025 (proj.) | F21: Notes
A22: S1 | B22: NHTSA-based: traffic deaths × medical-emergency share × non-seizure/diabetic remainder | C22: =C7*C9 -> 0.00208 | D22: =$C$5*C22 -> 81.64832 | E22: =$C$6*C22 -> 76.2112 | F22: Low-end. Treats the 1.3% crash share as a death share and assumes the whole remainder is cardiac (an upper bound within this method).
A23: S1b | B23: S1 adjusted upward for the higher severity of medical-emergency crashes | C23: =C7*C9*C12 -> 0.0052945455 | D23: =$C$5*C23 -> 207.83209 | E23: =$C$6*C23 -> 193.99215 | F23: Medical-emergency crashes are more often severe or fatal, so their share of deaths is likely above their share of crashes. Rough adjustment.
A24: S2 | B24: Switzerland (Vaud): probable cardiac arrest share | C24: =C13 -> 0.017 | D24: =$C$5*C24 -> 667.318 | E24: =$C$6*C24 -> 622.88 | F24: Applies a share of DRIVER deaths to ALL traffic deaths (incl. passengers, pedestrians), so it likely overstates. Old, non-US data.
A25: S3 | B25: Finland: probable cardiac arrest share | C25: =C14 -> 0.021 | D25: =$C$5*C25 -> 824.334 | E25: =$C$6*C25 -> 769.44 | F25: Same denominator caveat as S2. Old, non-US data.
B27: Low (minimum of scenarios) | D27: =MIN(D22:D25) -> 81.64832 | E27: =MIN(E22:E25) -> 76.2112
B28: High (maximum of scenarios) | D28: =MAX(D22:D25) -> 824.334 | E28: =MAX(E22:E25) -> 769.44
B29: Midpoint (average of scenarios) | D29: =AVERAGE(D22:D25) -> 445.2831 | E29: =AVERAGE(E22:E25) -> 415.63084
B30: Low as share of all US traffic deaths | D30: =D27/$C$5 -> 0.00208 | E30: =E27/$C$6 -> 0.00208
B31: High as share of all US traffic deaths | D31: =D28/$C$5 -> 0.021 | E31: =E28/$C$6 -> 0.021
A32: Read this as an order-of-magnitude range (roughly a hundred to under a thousand deaths a year), not a measurement. Scenarios differ in denominator, era and country.
A34: Context: deaths if the share applied were ALL medical causes (not heart-specific)
B35: Basis | C35: Share of traffic deaths | D35: Deaths — 2024 base | E35: Deaths — 2025 (proj.) | F35: Note
B36: NMVCCS: any driver medical emergency (crash share) | C36: =C7 -> 0.013 | D36: =$C$5*C36 -> 510.302 | E36: =$C$6*C36 -> 476.32 | F36: Source S13
B37: Finland: sudden driver incapacity, all causes | C37: =C15 -> 0.015 | D37: =$C$5*C37 -> 588.81 | E37: =$C$6*C37 -> 549.6 | F37: Source S15
B38: Vaud: sudden driver incapacity, all causes | C38: =C16 -> 0.034 | D38: =$C$5*C38 -> 1334.636 | E38: =$C$6*C38 -> 1245.76 | F38: Source S15
B39: Low end of reported range (any acute medical illness) | C39: =C17 -> 0.001 | D39: =$C$5*C39 -> 39.254 | E39: =$C$6*C39 -> 36.64 | F39: Source S14
B40: High end of reported range (any acute medical illness) | C40: =C18 -> 0.03 | D40: =$C$5*C40 -> 1177.62 | E40: =$C$6*C40 -> 1099.2 | F40: Source S14

Sheet Crash Case Data
A1: Breakdown: Who Dies in Crashes Linked to Heart Conditions — Study Data
A2: Counts and shares from individual studies (different countries and eras; not additive). Blue = reported figure; black = calculated.
A4: Study | B4: Metric | C4: Count / value | D4: Denominator | E4: Share | F4: Note | G4: Source ID
A5: Birmingham coroner, UK (1984-88) | B5: Natural deaths among motor-vehicle drivers (consecutive) | C5: 86 | F5: Starting population. | G5: S16
B6: …caused by ischaemic heart disease | C6: 80 | D6: =C5 -> 86 | E6: =C6/D6 -> 0.93023256 | F6: Ischaemic heart disease was the dominant cause of natural driver deaths.
B7: …cardiac deaths with prior cardiac history | C7: 51 | D7: =C6 -> 80 | E7: =C7/D7 -> 0.6375 | F7: Most had a known cardiac history.
B8: …cardiac deaths with reported chest pain beforehand | C8: 3 | D8: =C6 -> 80 | E8: =C8/D8 -> 0.0375 | F8: Few had warning symptoms.
B9: Vehicles involved in collisions | C9: 50 | F9: Abstract does not state the denominator.
B10: …collisions with properties | C10: 32 | F10: Categories may overlap (per abstract).
B11: …collisions with other vehicles | C11: 20
B12: …collisions with pedestrians | C12: 6
A13: Case series, China (2015-2019) | B13: Sudden deaths from ischemic heart disease while driving | C13: 21 | F13: Small case series. | G13: S17
B14: …with a history of hypertension | C14: 12 | D14: =C13 -> 21 | E14: =C14/D14 -> 0.57142857
B15: …with previous myocardial infarction | C15: 8 | D15: =C13 -> 21 | E15: =C15/D15 -> 0.38095238
B16: …with fatty liver | C16: 4 | D16: =C13 -> 21 | E16: =C16/D16 -> 0.19047619
A17: Antecol & Roberts, autopsy series (1990) | B17: Sudden natural deaths in the driver's seat | C17: 30 | F17: Automobile, truck or bus drivers. | G17: S18
B18: …cardiac arrest while driving | C18: 20 | D18: =C17 -> 30 | E18: =C18/D18 -> 0.66666667 | F18: Most drivers stopped the vehicle without injury to themselves or others.
B19: …while sitting in a parked vehicle | C19: 10 | D19: =C17 -> 30 | E19: =C19/D19 -> 0.33333333
A20: Sweden, Herner et al. (1959-63) | B20: Police-reported road accidents in one region | C20: 44255 | F20: Starting population. | G20: S19
B21: …caused or probably caused by sudden illness of the driver | C21: 41 | D21: =C20 -> 44255 | E21: =C21/D21 -> 0.00092644899 | F21: About 1 in 1,000 accidents; illness mostly epilepsy or myocardial infarction.
B22: …drivers who died at the wheel from the illness | C22: 8 | D22: =C21 -> 41 | E22: =C22/D22 -> 0.19512195 | F22: Share of the 41 illness-caused accidents.
B23: …other persons killed in those accidents | C23: 0 | F23: No other persons were killed.
A24: Finland & Vaud, Switzerland (1984-89) | B24: Driver deaths from sudden incapacity per million inhabitants per year — Finland | C24: 1.8 | F24: All acute illness, not heart-only. | G24: S15
B25: …Vaud | C25: 7.3
B26: Sudden incapacity — share of all traffic deaths, Finland | E26: 0.015 | F26: Reported share.
B27: Sudden incapacity — share of all traffic deaths, Vaud | E27: 0.034 | F27: Reported share.
B28: Probable cardiac arrest — share of all drivers' deaths, Finland | E28: 0.021 | F28: Reported share.
B29: Probable cardiac arrest — share of all drivers' deaths, Vaud | E29: 0.017 | F29: Reported share.
A30: NHTSA NMVCCS (national, light vehicles) | B30: Drivers in crashes precipitated by a medical emergency, % of all drivers | E30: 0.013 | F30: Reported share. | G30: S13, S23
B31: …seizures, blackouts or diabetic reactions | E31: 0.84 | F31: Share of medical-emergency drivers.
B32: Single-vehicle crashes — medical-emergency drivers | E32: 0.62
B33: Single-vehicle crashes — other drivers | E33: 0.17
B34: Sole occupant — medical-emergency drivers | E34: 0.85
B35: Sole occupant — other drivers | E35: 0.69
B36: Incapacitating injury or death — medical-emergency crashes | E36: 0.28
B37: Incapacitating injury or death — other crashes | E37: 0.11
A38: High-speed crash study (AAAM) | B38: High-speed crashes studied | C38: 124 | F38: Serious-injury crashes. | G38: S21
B39: …medical condition was the primary cause | C39: 7 | D39: =C38 -> 124 | E39: =C39/D39 -> 0.056451613 | F39: Study notes medical causes may be underreported in police reports.
B40: …medical condition possibly the cause | C40: 5 | D40: =C38 -> 124 | E40: =C40/D40 -> 0.040322581
B41: Of the 12 medical-condition crashes: diabetes | C41: 6 | D41: =C39+C40 -> 12 | E41: =C41/D41 -> 0.5 | F41: Denominator = 7 + 5 = 12 crashes.
...

Sheet Sources
A1: Sources, Data Quality & Limitations
A2: IDs (S1, S2, …) are referenced throughout the workbook. Retrieved October 2026.
A4: ID | B4: Source | C4: Used for | D4: Source type | E4: URL | F4: Quality note
A5: S1 | B5: CDC/NCHS FastStats — Deaths and Mortality / Leading Causes of Death (2024) | C5: Leading causes of death, total deaths | D5: Primary (agency) | E5: https://www.cdc.gov/nchs/FASTATS/deaths.htm | F5: Authoritative. Cause-of-death rankings are by count, not adjusted for age.
A6: S2 | B6: CDC — Heart Disease Facts | C6: US heart attacks per year (805,000) | D6: Primary (agency) | E6: https://www.cdc.gov/heart-disease/data-research/facts-stats/index.html | F6: Authoritative.
A7: S3 | B7: SafetyNow — Heart Attack Stats & Facts (summarizing CDC) | C7: Heart attack case fatality (~12%) | D7: Secondary summary | E7: https://ilt.safetynow.com/heart-attacks-stats-facts/ | F7: Secondary; also quotes older CDC totals. Verify against CDC.
A8: S4 | B8: ISHN — Stressful jobs increase heart attack risk (Lancet, Kivimäki) | C8: Job-strain RR and attributable share; smoking share | D8: News report of study | E8: https://ishn.com/articles/94124-stressful-jobs-increase-heart-attack-risk | F8: Not the original paper. Inactivity share differs from S5.
A9: S5 | B9: TIME Healthland — Work stress linked to more heart attacks | C9: Job-strain RR; association vs causation caveat; inactivity share | D9: News report of study | E9: https://healthland.time.com/?p=68985 | F9: Not the original paper.
A10: S6 | B10: ETUI — Psychosocial risk factors and acute MI (INTERHEART, Lancet 2004) | C10: INTERHEART stress, depression, smoking RR | D10: Summary of study | E10: https://hesa.etui-rehs.org/uk/newsevents/newsfiche.asp?pk=201 | F10: Trade-union institute summary of a peer-reviewed study.
A11: S7 | B11: Fox News — High-pressure deadlines up sudden heart attack risk (SHEEP) | C11: 6× risk within 24 h of sudden job stress | D11: News report of study | E11: https://www.foxnews.com/story/high-pressure-deadlines-up-sudden-heart-attack-risk.amp | F11: Not the original paper.
A12: S8 | B12: NewsOne — Katrina stress may still be causing heart attacks | C12: Tulane admissions before/after Katrina | D12: News report of study | E12: https://newsone.com/142141/katrina-stress-may-still-be-causing-heart-attacks/ | F12: Single hospital; catchment changed.
A13: S9 | B13: Daily Herald — 9/11 stress and heart problems (Holman et al.) | C13: +53% cardiovascular ailments | D13: News report of study | E13: https://www.dailyherald.com/?p=1064482 | F13: Self-reported diagnoses.
A14: S10 | B14: WRTV — The holidays bring a spike in heart attacks | C14: +4.2% heart-related deaths Dec 25 – Jan 7 | D14: News report of study | E14: https://wrtv.com/news/national/the-holidays-bring-a-spike-in-heart-attacks-heres-why | F14: Stress is one hypothesized explanation.
A15: S11 | B15: Trucknews — US traffic deaths decline again in 2025 (NHTSA) | C15: 2024 confirmed and 2025 projected traffic deaths | D15: News report of agency data | E15: https://www.trucknews.com/transportation/us-traffic-deaths-decline-again-in-2025/1003212143 | F15: 2025 is a projection.
... A27: S23 | B27: Lievers — driver health monitoring paper summarizing NHTSA 2009 study | C27: 28% vs 11% severity comparison | D27: Secondary summary | E27: https://wbldb.lievers.net/10139626.html | F27: Secondary; verify against NHTSA.
A29: Key limitations
A30: 1. No official statistic attributes deaths to 'stress'. Stress figures are relative risks and attributable fractions from observational studies — association, not proven causation.
A31: 2. No official US count of crash deaths caused by a driver's heart condition exists. 'Crash Estimates' is illustrative scenario arithmetic with a deliberately wide range.
A32: 3. Several crash studies are decades old, small, or non-US. Treat them as indicators of order of magnitude, not current US rates.
A33: 4. Several stress figures come from news reports of studies (see 'Source type'). Verify against the original papers before citing in formal work.
A34: 5. Medical causes of crashes are likely under-reported in police data (S21), so true counts may be higher.
A35: 6. This worksheet is for research and learning, not medical, legal or safety-engineering advice.
